from werkzeug.exceptions import HTTPException
from app.routes import validate_book
import pytest

def test_get_all_books_with_no_records(client):
    # Act
    response = client.get("/books")
    response_body = response.get_json()

    # Assert
    assert response.status_code == 200
    assert response_body == []

def test_get_one_book(client, two_saved_books):
    # Act
    response = client.get("/books/1")
    response_body = response.get_json()

    # Assert
    assert response.status_code == 200
    assert response_body == {
        "id": 1,
        "title": "Ocean Book",
        "description": "watr 4evr"
    }

def test_create_one_book(client):
    # Act
    response = client.post("/books", json={
        "title": "New Book",
        "description": "The Best!"
    })
    response_body = response.get_json()

    # Assert
    assert response.status_code == 201
    assert response_body == {
        "id": 1,
        "title": "New Book",
        "description": "The Best!"
    }

def test_validate_book(two_saved_books):
    # Act
    result_book = validate_book(1)

    # Assert
    assert result_book.id == 1
    assert result_book.title == "Ocean Book"
    assert result_book.description == "watr 4evr"

def test_validate_book_missing_record(two_saved_books):
    # Act & Assert
    # Calling `validate_book` without being invoked by a route will
    # cause an `HTTPException` when an `abort` statement is reached 
    with pytest.raises(HTTPException):
        result_book = validate_book("3")
    
def test_validate_book_invalid_id(two_saved_books):
    # Act & Assert
    # Calling `validate_book` without being invoked by a route will
    # cause an `HTTPException` when an `abort` statement is reached 
    with pytest.raises(HTTPException):
        result_book = validate_book("cat")